Workbook

Sheet Dashboard
A1: DRC EBOLA EPIDEMIOLOGY DASHBOARD | N1: Date | O1: Confirmed cases | P1: Confirmed deaths | Q1: Contacts | S1: Health zone | T1: Total cases | U1: Confirmed attack rate /100k
N2: Column1 | O2: Column2 | P2: Column3 | Q2: Column4 | S2: ='Location Analysis'!A2 | T2: ='Location Analysis'!G2 | U2: ='Location Analysis'!Q2
A3: Situation as of 2026-10-21 | Bundibugyo virus disease | Decision-support view | N3: =TEXT('Time Series'!A2,"dd-mmm") | O3: ='Time Series'!B2 | P3: ='Time Series'!E2 | Q3: ='Time Series'!H2 | S3: ='Location Analysis'!A3 | T3: ='Location Analysis'!G3 | U3: ='Location Analysis'!Q3
A4: Confirmed cases | D4: Confirmed deaths | G4: Confirmed CFR | J4: 7-day velocity | N4: =TEXT('Time Series'!A3,"dd-mmm") | O4: ='Time Series'!B3 | P4: ='Time Series'!E3 | Q4: ='Time Series'!H3 | S4: ='Location Analysis'!A4 | T4: ='Location Analysis'!G4 | U4: ='Location Analysis'!Q4
A5: =SUMIFS('Processed Data'!K:K, 'Processed Data'!H:H, "cases", 'Processed Data'!I:I, "confirmed", 'Processed Data'!G:G, MAX('Processed Data'!G:G)) | D5: ='Executive Summary'!B9 | G5: ='Executive Summary'!B12 | J5: ='Executive Summary'!B17 | N5: =TEXT('Time Series'!A4,"dd-mmm") | O5: ='Time Series'!B4 | P5: ='Time Series'!E4 | Q5: ='Time Series'!H4 | S5: ='Location Analysis'!A5 | T5: ='Location Analysis'!G5 | U5: ='Location Analysis'!Q5
N6: =TEXT('Time Series'!A5,"dd-mmm") | O6: ='Time Series'!B5 | P6: ='Time Series'!E5 | Q6: ='Time Series'!H5 | S6: ='Location Analysis'!A6 | T6: ='Location Analysis'!G6 | U6: ='Location Analysis'!Q6
N7: =TEXT('Time Series'!A6,"dd-mmm") | O7: ='Time Series'!B6 | P7: ='Time Series'!E6 | Q7: ='Time Series'!H6 | S7: ='Location Analysis'!A7 | T7: ='Location Analysis'!G7 | U7: ='Location Analysis'!Q7
N8: =TEXT('Time Series'!A7,"dd-mmm") | O8: ='Time Series'!B7 | P8: ='Time Series'!E7 | Q8: ='Time Series'!H7 | S8: ='Location Analysis'!A8 | T8: ='Location Analysis'!G8 | U8: ='Location Analysis'!Q8
A9: Epidemic trajectory | G9: Geographic burden | N9: =TEXT('Time Series'!A8,"dd-mmm") | O9: ='Time Series'!B8 | P9: ='Time Series'!E8 | Q9: ='Time Series'!H8 | S9: ='Location Analysis'!A9 | T9: ='Location Analysis'!G9 | U9: ='Location Analysis'!Q9
N10: =TEXT('Time Series'!A9,"dd-mmm") | O10: ='Time Series'!B9 | P10: ='Time Series'!E9 | Q10: ='Time Series'!H9 | S10: ='Location Analysis'!A10 | T10: ='Location Analysis'!G10 | U10: ='Location Analysis'!Q10
N11: =TEXT('Time Series'!A10,"dd-mmm") | O11: ='Time Series'!B10 | P11: ='Time Series'!E10 | Q11: ='Time Series'!H10 | S11: ='Location Analysis'!A11 | T11: ='Location Analysis'!G11 | U11: ='Location Analysis'!Q11
N12: =TEXT('Time Series'!A11,"dd-mmm") | O12: ='Time Series'!B11 | P12: ='Time Series'!E11 | Q12: ='Time Series'!H11 | S12: ='Location Analysis'!A12 | T12: ='Location Analysis'!G12 | U12: ='Location Analysis'!Q12
N13: =TEXT('Time Series'!A12,"dd-mmm") | O13: ='Time Series'!B12 | P13: ='Time Series'!E12 | Q13: ='Time Series'!H12 | S13: ='Location Analysis'!A13 | T13: ='Location Analysis'!G13 | U13: ='Location Analysis'!Q13
N14: =TEXT('Time Series'!A13,"dd-mmm") | O14: ='Time Series'!B13 | P14: ='Time Series'!E13 | Q14: ='Time Series'!H13
N15: =TEXT('Time Series'!A14,"dd-mmm") | O15: ='Time Series'!B14 | P15: ='Time Series'!E14 | Q15: ='Time Series'!H14
N16: =TEXT('Time Series'!A15,"dd-mmm") | O16: ='Time Series'!B15 | P16: ='Time Series'!E15 | Q16: ='Time Series'!H15
N17: =TEXT('Time Series'!A16,"dd-mmm") | O17: ='Time Series'!B16 | P17: ='Time Series'!E16 | Q17: ='Time Series'!H16
N18: =TEXT('Time Series'!A17,"dd-mmm") | O18: ='Time Series'!B17 | P18: ='Time Series'!E17 | Q18: ='Time Series'!H17
N19: =TEXT('Time Series'!A18,"dd-mmm") | O19: ='Time Series'!B18 | P19: ='Time Series'!E18 | Q19: ='Time Series'!H18
N20: =TEXT('Time Series'!A19,"dd-mmm") | O20: ='Time Series'!B19 | P20: ='Time Series'!E19 | Q20: ='Time Series'!H19
N21: =TEXT('Time Series'!A20,"dd-mmm") | O21: ='Time Series'!B20 | P21: ='Time Series'!E20 | Q21: ='Time Series'!H20
N22: =TEXT('Time Series'!A21,"dd-mmm") | O22: ='Time Series'!B21 | P22: ='Time Series'!E21 | Q22: ='Time Series'!H21
N23: =TEXT('Time Series'!A22,"dd-mmm") | O23: ='Time Series'!B22 | P23: ='Time Series'!E22 | Q23: ='Time Series'!H22
N24: =TEXT('Time Series'!A23,"dd-mmm") | O24: ='Time Series'!B23 | P24: ='Time Series'!E23 | Q24: ='Time Series'!H23
N25: =TEXT('Time Series'!A24,"dd-mmm") | O25: ='Time Series'!B24 | P25: ='Time Series'!E24 | Q25: ='Time Series'!H24
N26: =TEXT('Time Series'!A25,"dd-mmm") | O26: ='Time Series'!B25 | P26: ='Time Series'!E25 | Q26: ='Time Series'!H25
A27: Response signals | G27: Data reliability signals | N27: =TEXT('Time Series'!A26,"dd-mmm") | O27: ='Time Series'!B26 | P27: ='Time Series'!E26 | Q27: ='Time Series'!H26
A28: Accelerating burden: +856 confirmed cases in 7 days. Prioritize beds, PPE, oxygen/fluids, safe burial capacity, and laboratory throughput in the highest-burden zones. | G28: Contact and suspected series are 57 days stale. Restore daily line-list metrics before treating ratios as operational KPIs. | N28: =TEXT('Time Series'!A27,"dd-mmm") | O28: ='Time Series'!B27 | P28: ='Time Series'!E27 | Q28: ='Time Series'!H27
N29: =TEXT('Time Series'!A28,"dd-mmm") | O29: ='Time Series'!B28 | P29: ='Time Series'!E28 | Q29: ='Time Series'!H28
N30: =TEXT('Time Series'!A29,"dd-mmm") | O30: ='Time Series'!B29 | P30: ='Time Series'!E29 | Q30: ='Time Series'!H29
A31: Mobility-linked surveillance: intensify alert investigation and zero-reporting in Lita, Nizi, Bambu, Kilo and Nyakundé, while sustaining cross-border coordination with Uganda and South Sudan. | G31: 63 downward revisions and 83 missing-location rows: publish a daily reconciliation log and separate report-date from onset-date incidence. | N31: =TEXT('Time Series'!A30,"dd-mmm") | O31: ='Time Series'!B30 | P31: ='Time Series'!E30 | Q31: ='Time Series'!H30
N32: =TEXT('Time Series'!A31,"dd-mmm") | O32: ='Time Series'!B31 | P32: ='Time Series'!E31 | Q32: ='Time Series'!H31
N33: =TEXT('Time Series'!A32,"dd-mmm") | O33: ='Time Series'!B32 | P33: ='Time Series'!E32 | Q33: ='Time Series'!H32
N34: =TEXT('Time Series'!A33,"dd-mmm") | O34: ='Time Series'!B33 | P34: ='Time Series'!E33 | Q34: ='Time Series'!H33
N35: =TEXT('Time Series'!A34,"dd-mmm") | O35: ='Time Series'!B34 | P35: ='Time Series'!E34 | Q35: ='Time Series'!H34
N36: =TEXT('Time Series'!A35,"dd-mmm") | O36: ='Time Series'!B35 | P36: ='Time Series'!E35 | Q36: ='Time Series'!H35
N37: =TEXT('Time Series'!A36,"dd-mmm") | O37: ='Time Series'!B36 | P37: ='Time Series'!E36 | Q37: ='Time Series'!H36
N38: =TEXT('Time Series'!A37,"dd-mmm") | O38: ='Time Series'!B37 | P38: ='Time Series'!E37 | Q38: ='Time Series'!H37
N39: =TEXT('Time Series'!A38,"dd-mmm") | O39: ='Time Series'!B38 | P39: ='Time Series'!E38 | Q39: ='Time Series'!H38
N40: =TEXT('Time Series'!A39,"dd-mmm") | O40: ='Time Series'!B39 | P40: ='Time Series'!E39 | Q40: ='Time Series'!H39
...

Sheet Executive Summary
A1: DRC Ebola Epidemiology - Executive Summary
A3: Data cutoff: 2026-10-21 | Source series are cumulative snapshots
A5: Metric | B5: Value | D5: Interpretation and decision implications
A6: Confirmed cases | B6: 19530 | D6: Severity: Confirmed CFR is 43.8%, within the WHO historical Ebola range (25%-90%) and close to the general ~50% average. Outcome lag and reporting revisions remain important.
A7: Suspected cases | B7: 1007
A8: Total cases | B8: =B6+B7 | D8: Acceleration: Confirmed cases increased by 976 in the last 7 days (139.4 per day), while confirmed deaths increased by 498.
A9: Confirmed deaths | B9: 8961
A10: Suspected deaths | B10: 242 | D10: Concentration: 63.0% of latest total cases are concentrated in Bunia, Mongwalu and Rwampara, supporting surge deployment there while sustaining surveillance in mobility-linked zones.
A11: Total deaths | B11: =B9+B10
A12: Confirmed CFR | B12: =IFERROR(B9/B6,0) | D12: Contact tracing: Contacts were last updated on 2026-05-30; the current 1.08 contacts per confirmed case is stale and cannot establish tracing efficiency without follow-up/completion fields.
A13: All-classification CFR | B13: =IFERROR(B11/B8,0)
A14: Latest contacts | B14: 3550 | D14: Data risk: 63 downward cumulative revisions and 83 missing-location rows require reconciliation. Suspected case/death data also stop on 2026-05-30.
A15: Contacts / confirmed case | B15: =IFERROR(B14/B6,0)
A16: 7-day confirmed case growth | B16: 976
A17: 7-day confirmed velocity (per day) | B17: 139.42857
A18: Top-3 case concentration | B18: 0.63027758
A19: Locations with cases | B19: 52

Sheet Data Quality
A1: dimension | B1: check | C1: finding | D1: severity | E1: treatment
A2: Completeness | B2: Missing location | C2: 83 | D2: Critical | E2: Exclude from zone rates; retain as unallocated
A3: Completeness | B3: Missing classification | C3: 126 | D3: Expected for contacts | E3: Document as not applicable, not missing
A4: Timeliness | B4: Contacts end before cutoff | C4: 57 | D4: Critical | E4: Do not interpret current ratio as live tracing performance
A5: Timeliness | B5: Suspected series end before cutoff | C5: 57 | D5: Critical | E5: Treat total-case and all-case CFR trends after May 30 as stale
A6: Consistency | B6: Downward cumulative revisions | C6: 63 | D6: High | E6: Use net-change series and flag revisions
A7: Consistency | B7: Irregular reporting gaps | C7: 697 | D7: Moderate | E7: Carry forward only for current-snapshot display
A8: Redundancy | B8: Unchanged cumulative snapshots | C8: 2969 | D8: Informational | E8: Do not sum snapshots across dates
A9: Uniqueness | B9: Exact duplicate rows | C9: 0 | D9: Pass | E9: No action
A10: Validity | B10: Negative raw counts | C10: 0 | D10: Pass | E10: No action
A11: Validity | B11: Non-integer counts | C11: 0 | D11: Pass | E11: No action

Sheet Time Series
A1: measure | B1: cases | C1: deaths | D1: cases | E1: deaths
A2: case_classification | B2: confirmed | C2: suspected | D2: suspected | E2: confirmed
A3: reference_date
A4: 46156 | B4: 0 | C4: 57 | D4: 0 | E4: 0
A5: 46157 | B5: 13 | C5: 0 | D5: 80 | E5: 0
A6: 46160 | B6: 33 | C6: 131 | D6: 516 | E6: 0
A7: 46161 | B7: 51 | C7: 148 | D7: 575 | E7: 0
A8: 46162 | B8: 57 | C8: 160 | D8: 672 | E8: 0
A9: 46163 | B9: 79 | C9: 175 | D9: 745 | E9: 2
A10: 46164 | B10: 83 | C10: 204 | D10: 872 | E10: 5
A11: 46165 | B11: 95 | C11: 220 | D11: 905 | E11: 5
A12: 46166 | B12: 101 | C12: 223 | D12: 893 | E12: 5
A13: 46167 | B13: 100 | C13: 238 | D13: 998 | E13: 5
A14: 46168 | B14: 111 | C14: 246 | D14: 1064 | E14: 5
A15: 46169 | B15: 119 | C15: 223 | D15: 906 | E15: 5
... A72: 46238 | B72: 3973 | C72: 0 | D72: 0 | E72: 1801

Sheet Location Analysis
A1: location_key | B1: confirmed_cases | C1: suspected_cases | D1: confirmed_deaths | E1: suspected_deaths | F1: contacts | G1: total_cases | H1: total_deaths | I1: confirmed_cfr | J1: all_case_cfr | K1: contact_to_confirmed_case | L1: contact_to_all_case | M1: population_2023_est | N1: province | O1: source_url | P1: confirmed_attack_rate_per_100k | Q1: all_case_attack_rate_per_100k
A2: Bunia | B2: 773 | C2: 268 | D2: 220 | E2: 57 | F2: 404 | G2: 1041 | H2: 277 | I2: 0.28460543 | J2: 0.2660903 | K2: 0.52263907 | L2: 0.38808838 | M2: 229592 | N2: Ituri | O2: https://www.datocms-assets.com/30196/1780068452-2026-ebola-outbreak_unicef-drc-response-plan_maggio-2026.pdf | P2: 336.68421 | Q2: 453.41301
A3: Mongwalu | B3: 506 | C3: 346 | D3: 244 | E3: 88 | F3: 222 | G3: 852 | H3: 332 | I3: 0.48221344 | J3: 0.38967136 | K3: 0.43873518 | L3: 0.26056338 | M3: 114202 | N3: Ituri | O3: https://www.datocms-assets.com/30196/1780068452-2026-ebola-outbreak_unicef-drc-response-plan_maggio-2026.pdf | P3: 443.07455 | Q3: 746.04648
A4: Rwampara | B4: 568 | C4: 241 | D4: 241 | E4: 71 | F4: 697 | G4: 809 | H4: 312 | I4: 0.42429577 | J4: 0.38566131 | K4: 1.2271127 | L4: 0.86155748 | M4: 114800 | N4: Ituri | O4: https://www.datocms-assets.com/30196/1780068452-2026-ebola-outbreak_unicef-drc-response-plan_maggio-2026.pdf | P4: 494.77352 | Q4: 704.70383
A5: Nizi | B5: 357 | C5: 6 | D5: 171 | E5: 2 | F5: 260 | G5: 363 | H5: 173 | I5: 0.4789916 | J5: 0.47658402 | K5: 0.72829132 | L5: 0.71625344 | M5: 121293 | N5: Ituri | O5: https://www.datocms-assets.com/30196/1780068452-2026-ebola-outbreak_unicef-drc-response-plan_maggio-2026.pdf | P5: 294.32861 | Q5: 299.27531
A6: Nyakundé | B6: 114 | C6: 52 | D6: 31 | E6: 12 | F6: 743 | G6: 166 | H6: 43 | I6: 0.27192982 | J6: 0.25903614 | K6: 6.5175439 | L6: 4.4759036 | M6: 83872 | N6: Ituri | O6: https://www.datocms-assets.com/30196/1780068452-2026-ebola-outbreak_unicef-drc-response-plan_maggio-2026.pdf | P6: 135.9214 | Q6: 197.92064
A7: Katwa | B7: 140 | C7: 13 | D7: 88 | E7: 0 | F7: 221 | G7: 153 | H7: 88 | I7: 0.62857143 | J7: 0.5751634 | K7: 1.5785714 | L7: 1.4444444 | M7: 536895 | N7: Nord Kivu | O7: https://www.datocms-assets.com/30196/1780068452-2026-ebola-outbreak_unicef-drc-response-plan_maggio-2026.pdf | P7: 26.075862 | Q7: 28.497192
A8: Lita | B8: 117 | C8: 0 | D8: 66 | E8: 0 | F8: 0 | G8: 117 | H8: 66 | I8: 0.56410256 | J8: 0.56410256 | K8: 0 | L8: 0
A9: Mangala | B9: 100 | C9: 0 | D9: 64 | E9: 0 | F9: 0 | G9: 100 | H9: 64 | I9: 0.64 | J9: 0.64 | K9: 0 | L9: 0 | M9: 79344 | N9: Ituri | O9: https://www.datocms-assets.com/30196/1780068452-2026-ebola-outbreak_unicef-drc-response-plan_maggio-2026.pdf | P9: 126.03347 | Q9: 126.03347
A10: Nia-Nia | B10: 90 | C10: 0 | D10: 47 | E10: 0 | F10: 0 | G10: 90 | H10: 47 | I10: 0.52222222 | J10: 0.52222222 | K10: 0 | L10: 0
A11: Butembo | B11: 73 | C11: 7 | D11: 49 | E11: 0 | F11: 48 | G11: 80 | H11: 49 | I11: 0.67123288 | J11: 0.6125 | K11: 0.65753425 | L11: 0.6 | M11: 265999 | N11: Nord Kivu | O11: https://www.datocms-assets.com/30196/1780068452-2026-ebola-outbreak_unicef-drc-response-plan_maggio-2026.pdf | P11: 27.443712 | Q11: 30.075301
A12: Bambu | B12: 57 | C12: 14 | D12: 11 | E12: 3 | F12: 345 | G12: 71 | H12: 14 | I12: 0.19298246 | J12: 0.1971831 | K12: 6.0526316 | L12: 4.8591549 | M12: 121372 | N12: Ituri | O12: https://www.datocms-assets.com/30196/1780068452-2026-ebola-outbreak_unicef-drc-response-plan_maggio-2026.pdf | P12: 46.963056 | Q12: 58.497841
A13: Beni | B13: 44 | C13: 0 | D13: 34 | E13: 0 | F13: 0 | G13: 44 | H13: 34 | I13: 0.77272727 | J13: 0.77272727 | K13: 0 | L13: 0 | M13: 518212 | N13: Nord Kivu | O13: https://www.datocms-assets.com/30196/1780068452-2026-ebola-outbreak_unicef-drc-response-plan_maggio-2026.pdf | P13: 8.4907335 | Q13: 8.4907335
A14: Tchomia | B14: 40 | C14: 0 | D14: 24 | E14: 0 | F14: 0 | G14: 40 | H14: 24 | I14: 0.6 | J14: 0.6 | K14: 0 | L14: 0
A15: Komanda | B15: 35 | C15: 0 | D15: 24 | E15: 0 | F15: 0 | G15: 35 | H15: 24 | I15: 0.68571429 | J15: 0.68571429 | K15: 0 | L15: 0
A16: Kilo | B16: 23 | C16: 8 | D16: 11 | E16: 2 | F16: 41 | G16: 31 | H16: 13 | I16: 0.47826087 | J16: 0.41935484 | K16: 1.7826087 | L16: 1.3225806
A17: Musienene | B17: 29 | C17: 0 | D17: 19 | E17: 0 | F17: 0 | G17: 29 | H17: 19 | I17: 0.65517241 | J17: 0.65517241 | K17: 0 | L17: 0
A18: Rimba | B18: 8 | C18: 14 | D18: 4 | E18: 4 | F18: 0 | G18: 22 | H18: 8 | I18: 0.5 | J18: 0.36363636 | K18: 0 | L18: 0
A19: Kalunguta | B19: 5 | C19: 13 | D19: 3 | E19: 0 | F19: 0 | G19: 18 | H19: 3 | I19: 0.6 | J19: 0.16666667 | K19: 0 | L19: 0
A20: Fataki | B20: 17 | C20: 1 | D20: 6 | E20: 1 | F20: 0 | G20: 18 | H20: 7 | I20: 0.35294118 | J20: 0.38888889 | K20: 0 | L20: 0 | M20: 109828 | N20: Ituri | O20: https://www.datocms-assets.com/30196/1780068452-2026-ebola-outbreak_unicef-drc-response-plan_maggio-2026.pdf | P20: 15.478749 | Q20: 16.389263
A21: Damas | B21: 16 | C21: 1 | D21: 8 | E21: 0 | F21: 0 | G21: 17 | H21: 8 | I21: 0.5 | J21: 0.47058824 | K21: 0 | L21: 0
A22: [Unallocated] | B22: 17 | C22: 0 | D22: 0 | E22: 0 | F22: 0 | G22: 17 | H22: 0 | I22: 0 | J22: 0 | K22: 0 | L22: 0
A23: Kyondo | B23: 12 | C23: 3 | D23: 7 | E23: 0 | F23: 16 | G23: 15 | H23: 7 | I23: 0.58333333 | J23: 0.46666667 | K23: 1.3333333 | L23: 1.0666667
A24: Mambasa | B24: 9 | C24: 5 | D24: 4 | E24: 1 | F24: 0 | G24: 14 | H24: 5 | I24: 0.44444444 | J24: 0.35714286 | K24: 0 | L24: 0
A25: Mandima | B25: 13 | C25: 0 | D25: 9 | E25: 0 | F25: 0 | G25: 13 | H25: 9 | I25: 0.69230769 | J25: 0.69230769 | K25: 0 | L25: 0
A26: Isiro | B26: 12 | C26: 0 | D26: 7 | E26: 0 | F26: 0 | G26: 12 | H26: 7 | I26: 0.58333333 | J26: 0.58333333 | K26: 0 | L26: 0
A27: Wamba | B27: 11 | C27: 0 | D27: 4 | E27: 0 | F27: 0 | G27: 11 | H27: 4 | I27: 0.36363636 | J27: 0.36363636 | K27: 0 | L27: 0
A28: Adja | B28: 11 | C28: 0 | D28: 1 | E28: 0 | F28: 0 | G28: 11 | H28: 1 | I28: 0.090909091 | J28: 0.090909091 | K28: 0 | L28: 0
A29: Drodro | B29: 10 | C29: 0 | D29: 5 | E29: 0 | F29: 0 | G29: 10 | H29: 5 | I29: 0.5 | J29: 0.5 | K29: 0 | L29: 0
A30: Logo | B30: 9 | C30: 0 | D30: 3 | E30: 0 | F30: 0 | G30: 9 | H30: 3 | I30: 0.33333333 | J30: 0.33333333 | K30: 0 | L30: 0 | M30: 205979 | N30: Ituri | O30: https://www.datocms-assets.com/30196/1780068452-2026-ebola-outbreak_unicef-drc-response-plan_maggio-2026.pdf | P30: 4.3693775 | Q30: 4.3693775
A31: Aru | B31: 5 | C31: 4 | D31: 5 | E31: 1 | F31: 0 | G31: 9 | H31: 6 | I31: 1 | J31: 0.66666667 | K31: 0 | L31: 0
A32: Pawa | B32: 8 | C32: 0 | D32: 6 | E32: 0 | F32: 0 | G32: 8 | H32: 6 | I32: 0.75 | J32: 0.75 | K32: 0 | L32: 0
A33: Ariwara | B33: 7 | C33: 0 | D33: 1 | E33: 0 | F33: 0 | G33: 7 | H33: 1 | I33: 0.14285714 | J33: 0.14285714 | K33: 0 | L33: 0
A34: Boma-Mangbetu | B34: 7 | C34: 0 | D34: 4 | E34: 0 | F34: 0 | G34: 7 | H34: 4 | I34: 0.57142857 | J34: 0.57142857 | K34: 0 | L34: 0
A35: Aungba | B35: 5 | C35: 0 | D35: 4 | E35: 0 | F35: 0 | G35: 5 | H35: 4 | I35: 0.8 | J35: 0.8 | K35: 0 | L35: 0
A36: Karisimbi | B36: 0 | C36: 5 | D36: 0 | E36: 0 | F36: 413 | G36: 5 | H36: 0 | J36: 0 | L36: 82.6 | M36: 641981 | N36: Nord Kivu | O36: https://www.datocms-assets.com/30196/1780068452-2026-ebola-outbreak_unicef-drc-response-plan_maggio-2026.pdf | P36: 0 | Q36: 0.77883925
A37: Gethy | B37: 1 | C37: 3 | D37: 0 | E37: 0 | F37: 0 | G37: 4 | H37: 0 | I37: 0 | J37: 0 | K37: 0 | L37: 0
A38: Miti-murhesa | B38: 3 | C38: 1 | D38: 1 | E38: 0 | F38: 0 | G38: 4 | H38: 1 | I38: 0.33333333 | J38: 0.25 | K38: 0 | L38: 0 | M38: 285000 | N38: Sud Kivu | O38: https://www.datocms-assets.com/30196/1780068452-2026-ebola-outbreak_unicef-drc-response-plan_maggio-2026.pdf | P38: 1.0526316 | Q38: 1.4035088
A39: Oicha | B39: 4 | C39: 0 | D39: 3 | E39: 0 | F39: 0 | G39: 4 | H39: 3 | I39: 0.75 | J39: 0.75 | K39: 0 | L39: 0
A40: Masereka | B40: 4 | C40: 0 | D40: 0 | E40: 0 | F40: 0 | G40: 4 | H40: 0 | I40: 0 | J40: 0 | K40: 0 | L40: 0
...

Sheet KPI Dictionary
A1: indicator | B1: unit | C1: definition | D1: frequency | E1: use | F1: status
A2: Confirmed cases | B2: count | C2: Latest cumulative confirmed cases | D2: Daily | E2: Situation awareness | F2: Available
A3: Confirmed deaths | B3: count | C3: Latest cumulative confirmed deaths | D3: Daily | E3: Severity | F3: Available
A4: Confirmed CFR | B4: % | C4: Confirmed deaths / confirmed cases | D4: Daily | E4: Severity benchmark vs 25%-90% historical Ebola range | F4: Available; outcome lag caveat
A5: 7-day case velocity | B5: cases/day | C5: Change in confirmed cases over 7 days / 7 | D5: Daily | E5: Transmission/reporting momentum | F5: Available
A6: 7-day death velocity | B6: deaths/day | C6: Change in confirmed deaths over 7 days / 7 | D6: Daily | E6: Mortality momentum | F6: Available
A7: Contact-to-confirmed-case ratio | B7: contacts/case | C7: Current contacts / confirmed cases | D7: Daily | E7: Contact identification breadth | F7: Stale after 2026-05-30
A8: Contact follow-up completion | B8: % | C8: Contacts seen / contacts listed | D8: Daily | E8: Tracing execution | F8: Not available
A9: Lost-to-follow-up rate | B9: % | C9: Contacts lost / contacts listed | D9: Daily | E9: Tracing failure | F9: Not available
A10: Attack rate | B10: cases/100,000 | C10: Cumulative cases / health-zone population x 100,000 | D10: Daily | E10: Population burden | F10: Available for 15 matched zones
A11: Geographic spread | B11: health zones | C11: Zones with at least one case | D11: Daily | E11: Spatial expansion | F11: Available
A12: Top-3 concentration | B12: % | C12: Share of all cases in three highest-burden zones | D12: Daily | E12: Operational concentration | F12: Available
... A14: Reporting timeliness | B14: days | C14: Cutoff minus latest report by series | D14: Daily | E14: Data reliability | F14: Available

Sheet Population
A1: location_key | B1: population_2023_est | C1: province | D1: source_url
A2: Bunia | B2: 229592 | C2: Ituri | D2: https://www.datocms-assets.com/30196/1780068452-2026-ebola-outbreak_unicef-drc-response-plan_maggio-2026.pdf
A3: Rwampara | B3: 114800 | C3: Ituri | D3: https://www.datocms-assets.com/30196/1780068452-2026-ebola-outbreak_unicef-drc-response-plan_maggio-2026.pdf
A4: Mongwalu | B4: 114202 | C4: Ituri | D4: https://www.datocms-assets.com/30196/1780068452-2026-ebola-outbreak_unicef-drc-response-plan_maggio-2026.pdf
A5: Logo | B5: 205979 | C5: Ituri | D5: https://www.datocms-assets.com/30196/1780068452-2026-ebola-outbreak_unicef-drc-response-plan_maggio-2026.pdf
A6: Fataki | B6: 109828 | C6: Ituri | D6: https://www.datocms-assets.com/30196/1780068452-2026-ebola-outbreak_unicef-drc-response-plan_maggio-2026.pdf
A7: Nizi | B7: 121293 | C7: Ituri | D7: https://www.datocms-assets.com/30196/1780068452-2026-ebola-outbreak_unicef-drc-response-plan_maggio-2026.pdf
A8: Bambu | B8: 121372 | C8: Ituri | D8: https://www.datocms-assets.com/30196/1780068452-2026-ebola-outbreak_unicef-drc-response-plan_maggio-2026.pdf
A9: Mangala | B9: 79344 | C9: Ituri | D9: https://www.datocms-assets.com/30196/1780068452-2026-ebola-outbreak_unicef-drc-response-plan_maggio-2026.pdf
A10: Nyakundé | B10: 83872 | C10: Ituri | D10: https://www.datocms-assets.com/30196/1780068452-2026-ebola-outbreak_unicef-drc-response-plan_maggio-2026.pdf
A11: Katwa | B11: 536895 | C11: Nord Kivu | D11: https://www.datocms-assets.com/30196/1780068452-2026-ebola-outbreak_unicef-drc-response-plan_maggio-2026.pdf
A12: Goma | B12: 245545 | C12: Nord Kivu | D12: https://www.datocms-assets.com/30196/1780068452-2026-ebola-outbreak_unicef-drc-response-plan_maggio-2026.pdf
A13: Karisimbi | B13: 641981 | C13: Nord Kivu | D13: https://www.datocms-assets.com/30196/1780068452-2026-ebola-outbreak_unicef-drc-response-plan_maggio-2026.pdf
... A16: Miti-murhesa | B16: 285000 | C16: Sud Kivu | D16: https://www.datocms-assets.com/30196/1780068452-2026-ebola-outbreak_unicef-drc-response-plan_maggio-2026.pdf

Sheet Sources
A1: source | B1: use | C1: url
A2: WHO Ebola fact sheet | B2: Historical Ebola CFR 25%-90%; average around 50%; response package | C2: https://www.who.int/news-room/fact-sheets/detail/ebola-disease
A3: WHO DON606, 11 Jun 2026 | B3: Confirmed-case/death context, backlog warning, risk assessment | C3: https://www.who.int/emergencies/disease-outbreak-news/item/2026-DON606
A4: WHO DON602, 21 May 2026 | B4: Outbreak declaration, early event context, BVD CFR 30%-50% in prior outbreaks | C4: https://www.who.int/emergencies/disease-outbreak-news/item/2026-DON602
A5: UNICEF DRC response plan, May 2026 | B5: 2023 estimated health-zone populations used for attack-rate denominators | C5: https://www.datocms-assets.com/30196/1780068452-2026-ebola-outbreak_unicef-drc-response-plan_maggio-2026.pdf
A6: Flowminder mobility report, 4 Jun 2026 | B6: Mobility-based importation risk and priority destination zones | C6: https://www.flowminder.org/resources/publications-reports/drc-reports-publications/population-movements-from-bunia-mongbwalu-and-rwampara-based-on-privacy-secure-analysis-of-mobile-operator-data-from-vodacom-congo-04-june-2026

Sheet Raw Data
A1: location_name | B1: reference_date | C1: Period | D1: Column1 | E1: measure | F1: case_classification | G1: time_period | H1: Count
A2: Mongbalu | B2: 46156 | C2: May -Wk2 | D2: May | E2: cases | F2: confirmed | G2: cumulative | H2: 0
A3: Mongbalu | B3: 46156 | C3: May -Wk2 | D3: May | E3: contacts | G3: cumulative | H3: 82
A4: Mongbalu | B4: 46156 | C4: May -Wk2 | D4: May | E4: deaths | F4: suspected | G4: cumulative | H4: 57
A5: Bunia | B5: 46157 | C5: May -Wk3 | D5: May | E5: cases | F5: confirmed | G5: cumulative | H5: 0
A6: Bunia | B6: 46157 | C6: May -Wk3 | D6: May | E6: cases | F6: suspected | G6: cumulative | H6: 8
A7: Mongbalu | B7: 46157 | C7: May -Wk3 | D7: May | E7: cases | F7: confirmed | G7: cumulative | H7: 0
A8: Rwampara | B8: 46157 | C8: May -Wk3 | D8: May | E8: cases | F8: confirmed | G8: cumulative | H8: 13
A9: Rwampara | B9: 46157 | C9: May -Wk3 | D9: May | E9: cases | F9: suspected | G9: cumulative | H9: 72
A10: Bunia | B10: 46160 | C10: May -Wk3 | D10: May | E10: cases | F10: confirmed | G10: cumulative | H10: 6
A11: Bunia | B11: 46160 | C11: May -Wk3 | D11: May | E11: cases | F11: suspected | G11: cumulative | H11: 61
A12: Bunia | B12: 46160 | C12: May -Wk3 | D12: May | E12: contacts | G12: cumulative | H12: 127
A13: Bunia | B13: 46160 | C13: May -Wk3 | D13: May | E13: deaths | F13: suspected | G13: cumulative | H13: 18
A14: Butembo | B14: 46160 | C14: May -Wk3 | D14: May | E14: cases | F14: confirmed | G14: cumulative | H14: 1
A15: Butembo | B15: 46160 | C15: May -Wk3 | D15: May | E15: cases | F15: suspected | G15: cumulative | H15: 1
A16: Goma | B16: 46160 | C16: May -Wk3 | D16: May | E16: cases | F16: confirmed | G16: cumulative | H16: 1
A17: Goma | B17: 46160 | C17: May -Wk3 | D17: May | E17: cases | F17: suspected | G17: cumulative | H17: 1
A18: Katwa | B18: 46160 | C18: May -Wk3 | D18: May | E18: cases | F18: confirmed | G18: cumulative | H18: 1
A19: Katwa | B19: 46160 | C19: May -Wk3 | D19: May | E19: cases | F19: suspected | G19: cumulative | H19: 1
A20: Mongbalu | B20: 46160 | C20: May -Wk3 | D20: May | E20: cases | F20: confirmed | G20: cumulative | H20: 1
A21: Mongbalu | B21: 46160 | C21: May -Wk3 | D21: May | E21: cases | F21: suspected | G21: cumulative | H21: 302
A22: Mongbalu | B22: 46160 | C22: May -Wk3 | D22: May | E22: contacts | G22: cumulative | H22: 161
A23: Mongbalu | B23: 46160 | C23: May -Wk3 | D23: May | E23: deaths | F23: suspected | G23: cumulative | H23: 74
A24: Nyakunde | B24: 46160 | C24: May -Wk3 | D24: May | E24: cases | F24: confirmed | G24: cumulative | H24: 4
A25: Nyakunde | B25: 46160 | C25: May -Wk3 | D25: May | E25: cases | F25: suspected | G25: cumulative | H25: 14
A26: Nyakunde | B26: 46160 | C26: May -Wk3 | D26: May | E26: contacts | G26: cumulative | H26: 133
A27: Nyakunde | B27: 46160 | C27: May -Wk3 | D27: May | E27: deaths | F27: suspected | G27: cumulative | H27: 1
A28: Rwampara | B28: 46160 | C28: May -Wk3 | D28: May | E28: cases | F28: confirmed | G28: cumulative | H28: 19
A29: Rwampara | B29: 46160 | C29: May -Wk3 | D29: May | E29: cases | F29: suspected | G29: cumulative | H29: 136
A30: Rwampara | B30: 46160 | C30: May -Wk3 | D30: May | E30: contacts | G30: cumulative | H30: 120
A31: Rwampara | B31: 46160 | C31: May -Wk3 | D31: May | E31: deaths | F31: suspected | G31: cumulative | H31: 38
A32: Bunia | B32: 46161 | C32: May -Wk3 | D32: May | E32: cases | F32: confirmed | G32: cumulative | H32: 6
A33: Bunia | B33: 46161 | C33: May -Wk3 | D33: May | E33: cases | F33: suspected | G33: cumulative | H33: 90
A34: Bunia | B34: 46161 | C34: May -Wk3 | D34: May | E34: contacts | G34: cumulative | H34: 203
A35: Bunia | B35: 46161 | C35: May -Wk3 | D35: May | E35: deaths | F35: confirmed | G35: cumulative | H35: 0
A36: Bunia | B36: 46161 | C36: May -Wk3 | D36: May | E36: deaths | F36: suspected | G36: cumulative | H36: 23
A37: Butembo | B37: 46161 | C37: May -Wk3 | D37: May | E37: cases | F37: confirmed | G37: cumulative | H37: 1
A38: Butembo | B38: 46161 | C38: May -Wk3 | D38: May | E38: cases | F38: suspected | G38: cumulative | H38: 1
A39: Goma | B39: 46161 | C39: May -Wk3 | D39: May | E39: cases | F39: confirmed | G39: cumulative | H39: 1
A40: Goma | B40: 46161 | C40: May -Wk3 | D40: May | E40: cases | F40: suspected | G40: cumulative | H40: 1
...

Sheet Processed Data
A1: location_country | B1: location_level | C1: location_name | D1: location_name_source | E1: location_code | F1: location_code_type | G1: reference_date | H1: measure | I1: case_classification | J1: time_period | K1: value | L1: unit | M1: source | N1: source_url | O1: source_indicator_name | P1: indicator_label | Q1: reporting_period_start | R1: reporting_period_end | S1: last_updated | T1: data_quality_flag | U1: notes | V1: previous_value | W1: daily_net_change | X1: previous_date | Y1: days_since_last_report | Z1: dq_status | AA1: velocity_7day
A2: COD | B2: 3 | C2: Adja | D2: Adja | E2: CD540902 | F2: pcode | G2: 46222 | H2: cases | I2: confirmed | J2: cumulative | K2: 10 | L2: count | M2: INRB-UMIE | N2: https://raw.githubusercontent.com/INRB-UMIE/BDBV2026-Data/main/data/insp_sitrep/processed/insp_sitrep__cumulative_confirmed_cases__daily.csv | Z2: Normal
A3: COD | B3: 3 | C3: Adja | D3: Adja | E3: CD540902 | F3: pcode | G3: 46223 | H3: cases | I3: confirmed | J3: cumulative | K3: 10 | L3: count | M3: INRB-UMIE | N3: https://raw.githubusercontent.com/INRB-UMIE/BDBV2026-Data/main/data/insp_sitrep/processed/insp_sitrep__cumulative_confirmed_cases__daily.csv | V3: 10 | W3: 0 | X3: 46222 | Y3: 1 | Z3: Normal | AA3: 0
A4: COD | B4: 3 | C4: Adja | D4: Adja | E4: CD540902 | F4: pcode | G4: 46225 | H4: cases | I4: confirmed | J4: cumulative | K4: 10 | L4: count | M4: INRB-UMIE | N4: https://raw.githubusercontent.com/INRB-UMIE/BDBV2026-Data/main/data/insp_sitrep/processed/insp_sitrep__cumulative_confirmed_cases__daily.csv | V4: 10 | W4: 0 | X4: 46223 | Y4: 2 | Z4: Reporting Gap (>1 Day) | AA4: 0
A5: COD | B5: 3 | C5: Adja | D5: Adja | E5: CD540902 | F5: pcode | G5: 46226 | H5: cases | I5: confirmed | J5: cumulative | K5: 10 | L5: count | M5: INRB-UMIE | N5: https://raw.githubusercontent.com/INRB-UMIE/BDBV2026-Data/main/data/insp_sitrep/processed/insp_sitrep__cumulative_confirmed_cases__daily.csv | V5: 10 | W5: 0 | X5: 46225 | Y5: 1 | Z5: Normal | AA5: 0
A6: COD | B6: 3 | C6: Adja | D6: Adja | E6: CD540902 | F6: pcode | G6: 46228 | H6: cases | I6: confirmed | J6: cumulative | K6: 11 | L6: count | M6: INRB-UMIE | N6: https://raw.githubusercontent.com/INRB-UMIE/BDBV2026-Data/main/data/insp_sitrep/processed/insp_sitrep__cumulative_confirmed_cases__daily.csv | V6: 10 | W6: 1 | X6: 46226 | Y6: 2 | Z6: Reporting Gap (>1 Day) | AA6: 0.25
A7: COD | B7: 3 | C7: Adja | D7: Adja | E7: CD540902 | F7: pcode | G7: 46229 | H7: cases | I7: confirmed | J7: cumulative | K7: 11 | L7: count | M7: INRB-UMIE | N7: https://raw.githubusercontent.com/INRB-UMIE/BDBV2026-Data/main/data/insp_sitrep/processed/insp_sitrep__cumulative_confirmed_cases__daily.csv | V7: 11 | W7: 0 | X7: 46228 | Y7: 1 | Z7: Normal | AA7: 0.2
A8: COD | B8: 3 | C8: Adja | D8: Adja | E8: CD540902 | F8: pcode | G8: 46230 | H8: cases | I8: confirmed | J8: cumulative | K8: 11 | L8: count | M8: INRB-UMIE | N8: https://raw.githubusercontent.com/INRB-UMIE/BDBV2026-Data/main/data/insp_sitrep/processed/insp_sitrep__cumulative_confirmed_cases__daily.csv | V8: 11 | W8: 0 | X8: 46229 | Y8: 1 | Z8: Normal | AA8: 0.16666667
A9: COD | B9: 3 | C9: Adja | D9: Adja | E9: CD540902 | F9: pcode | G9: 46233 | H9: cases | I9: confirmed | J9: cumulative | K9: 11 | L9: count | M9: INRB-UMIE | N9: https://raw.githubusercontent.com/INRB-UMIE/BDBV2026-Data/main/data/insp_sitrep/processed/insp_sitrep__cumulative_confirmed_cases__daily.csv | V9: 11 | W9: 0 | X9: 46230 | Y9: 3 | Z9: Reporting Gap (>1 Day) | AA9: 0.14285714
A10: COD | B10: 3 | C10: Adja | D10: Adja | E10: CD540902 | F10: pcode | G10: 46234 | H10: cases | I10: confirmed | J10: cumulative | K10: 11 | L10: count | M10: INRB-UMIE | N10: https://raw.githubusercontent.com/INRB-UMIE/BDBV2026-Data/main/data/insp_sitrep/processed/insp_sitrep__cumulative_confirmed_cases__daily.csv | V10: 11 | W10: 0 | X10: 46233 | Y10: 1 | Z10: Normal | AA10: 0.14285714
A11: COD | B11: 3 | C11: Adja | D11: Adja | E11: CD540902 | F11: pcode | G11: 46235 | H11: cases | I11: confirmed | J11: cumulative | K11: 11 | L11: count | M11: INRB-UMIE | N11: https://raw.githubusercontent.com/INRB-UMIE/BDBV2026-Data/main/data/insp_sitrep/processed/insp_sitrep__cumulative_confirmed_cases__daily.csv | V11: 11 | W11: 0 | X11: 46234 | Y11: 1 | Z11: Normal | AA11: 0.14285714
A12: COD | B12: 3 | C12: Adja | D12: Adja | E12: CD540902 | F12: pcode | G12: 46236 | H12: cases | I12: confirmed | J12: cumulative | K12: 11 | L12: count | M12: INRB-UMIE | N12: https://raw.githubusercontent.com/INRB-UMIE/BDBV2026-Data/main/data/insp_sitrep/processed/insp_sitrep__cumulative_confirmed_cases__daily.csv | V12: 11 | W12: 0 | X12: 46235 | Y12: 1 | Z12: Normal | AA12: 0.14285714
A13: COD | B13: 3 | C13: Adja | D13: Adja | E13: CD540902 | F13: pcode | G13: 46237 | H13: cases | I13: confirmed | J13: cumulative | K13: 11 | L13: count | M13: INRB-UMIE | N13: https://raw.githubusercontent.com/INRB-UMIE/BDBV2026-Data/main/data/insp_sitrep/processed/insp_sitrep__cumulative_confirmed_cases__daily.csv | V13: 11 | W13: 0 | X13: 46236 | Y13: 1 | Z13: Normal | AA13: 0
A14: COD | B14: 3 | C14: Adja | D14: Adja | E14: CD540902 | F14: pcode | G14: 46238 | H14: cases | I14: confirmed | J14: cumulative | K14: 11 | L14: count | M14: INRB-UMIE | N14: https://raw.githubusercontent.com/INRB-UMIE/BDBV2026-Data/main/data/insp_sitrep/processed/insp_sitrep__cumulative_confirmed_cases__daily.csv | V14: 11 | W14: 0 | X14: 46237 | Y14: 1 | Z14: Normal | AA14: 0
... A74: COD | B74: 3 | C74: Adja | D74: Adja | E74: CD540902 | F74: pcode | G74: 46316 | H74: cases | I74: confirmed | J74: cumulative | K74: 11 | L74: count | M74: INRB-UMIE | N74: https://raw.githubusercontent.com/INRB-UMIE/BDBV2026-Data/main/data/insp_sitrep/processed/insp_sitrep__cumulative_confirmed_cases__daily.csv | V74: 11 | W74: 0 | X74: 46314 | Y74: 2 | Z74: Reporting Gap (>1 Day) | AA74: 0
A75: COD | B75: 3 | C75: Adja | D75: Adja | E75: CD540902 | F75: pcode | G75: 46222 | H75: deaths | I75: confirmed | J75: cumulative | K75: 1 | L75: count | M75: INRB-UMIE | N75: https://raw.githubusercontent.com/INRB-UMIE/BDBV2026-Data/main/data/insp_sitrep/processed/insp_sitrep__cumulative_confirmed_deaths__daily.csv | Z75: Normal
A76: COD | B76: 3 | C76: Adja | D76: Adja | E76: CD540902 | F76: pcode | G76: 46223 | H76: deaths | I76: confirmed | J76: cumulative | K76: 1 | L76: count | M76: INRB-UMIE | N76: https://raw.githubusercontent.com/INRB-UMIE/BDBV2026-Data/main/data/insp_sitrep/processed/insp_sitrep__cumulative_confirmed_deaths__daily.csv | V76: 1 | W76: 0 | X76: 46222 | Y76: 1 | Z76: Normal | AA76: 0
A77: COD | B77: 3 | C77: Adja | D77: Adja | E77: CD540902 | F77: pcode | G77: 46225 | H77: deaths | I77: confirmed | J77: cumulative | K77: 1 | L77: count | M77: INRB-UMIE | N77: https://raw.githubusercontent.com/INRB-UMIE/BDBV2026-Data/main/data/insp_sitrep/processed/insp_sitrep__cumulative_confirmed_deaths__daily.csv | V77: 1 | W77: 0 | X77: 46223 | Y77: 2 | Z77: Reporting Gap (>1 Day) | AA77: 0
A78: COD | B78: 3 | C78: Adja | D78: Adja | E78: CD540902 | F78: pcode | G78: 46226 | H78: deaths | I78: confirmed | J78: cumulative | K78: 1 | L78: count | M78: INRB-UMIE | N78: https://raw.githubusercontent.com/INRB-UMIE/BDBV2026-Data/main/data/insp_sitrep/processed/insp_sitrep__cumulative_confirmed_deaths__daily.csv | V78: 1 | W78: 0 | X78: 46225 | Y78: 1 | Z78: Normal | AA78: 0
A79: COD | B79: 3 | C79: Adja | D79: Adja | E79: CD540902 | F79: pcode | G79: 46228 | H79: deaths | I79: confirmed | J79: cumulative | K79: 1 | L79: count | M79: INRB-UMIE | N79: https://raw.githubusercontent.com/INRB-UMIE/BDBV2026-Data/main/data/insp_sitrep/processed/insp_sitrep__cumulative_confirmed_deaths__daily.csv | V79: 1 | W79: 0 | X79: 46226 | Y79: 2 | Z79: Reporting Gap (>1 Day) | AA79: 0
A80: COD | B80: 3 | C80: Adja | D80: Adja | E80: CD540902 | F80: pcode | G80: 46229 | H80: deaths | I80: confirmed | J80: cumulative | K80: 1 | L80: count | M80: INRB-UMIE | N80: https://raw.githubusercontent.com/INRB-UMIE/BDBV2026-Data/main/data/insp_sitrep/processed/insp_sitrep__cumulative_confirmed_deaths__daily.csv | V80: 1 | W80: 0 | X80: 46228 | Y80: 1 | Z80: Normal | AA80: 0
A81: COD | B81: 3 | C81: Adja | D81: Adja | E81: CD540902 | F81: pcode | G81: 46230 | H81: deaths | I81: confirmed | J81: cumulative | K81: 1 | L81: count | M81: INRB-UMIE | N81: https://raw.githubusercontent.com/INRB-UMIE/BDBV2026-Data/main/data/insp_sitrep/processed/insp_sitrep__cumulative_confirmed_deaths__daily.csv | V81: 1 | W81: 0 | X81: 46229 | Y81: 1 | Z81: Normal | AA81: 0
A82: COD | B82: 3 | C82: Adja | D82: Adja | E82: CD540902 | F82: pcode | G82: 46233 | H82: deaths | I82: confirmed | J82: cumulative | K82: 1 | L82: count | M82: INRB-UMIE | N82: https://raw.githubusercontent.com/INRB-UMIE/BDBV2026-Data/main/data/insp_sitrep/processed/insp_sitrep__cumulative_confirmed_deaths__daily.csv | V82: 1 | W82: 0 | X82: 46230 | Y82: 3 | Z82: Reporting Gap (>1 Day) | AA82: 0
A83: COD | B83: 3 | C83: Adja | D83: Adja | E83: CD540902 | F83: pcode | G83: 46234 | H83: deaths | I83: confirmed | J83: cumulative | K83: 1 | L83: count | M83: INRB-UMIE | N83: https://raw.githubusercontent.com/INRB-UMIE/BDBV2026-Data/main/data/insp_sitrep/processed/insp_sitrep__cumulative_confirmed_deaths__daily.csv | V83: 1 | W83: 0 | X83: 46233 | Y83: 1 | Z83: Normal | AA83: 0
A84: COD | B84: 3 | C84: Adja | D84: Adja | E84: CD540902 | F84: pcode | G84: 46235 | H84: deaths | I84: confirmed | J84: cumulative | K84: 1 | L84: count | M84: INRB-UMIE | N84: https://raw.githubusercontent.com/INRB-UMIE/BDBV2026-Data/main/data/insp_sitrep/processed/insp_sitrep__cumulative_confirmed_deaths__daily.csv | V84: 1 | W84: 0 | X84: 46234 | Y84: 1 | Z84: Normal | AA84: 0
A85: COD | B85: 3 | C85: Adja | D85: Adja | E85: CD540902 | F85: pcode | G85: 46236 | H85: deaths | I85: confirmed | J85: cumulative | K85: 1 | L85: count | M85: INRB-UMIE | N85: https://raw.githubusercontent.com/INRB-UMIE/BDBV2026-Data/main/data/insp_sitrep/processed/insp_sitrep__cumulative_confirmed_deaths__daily.csv | V85: 1 | W85: 0 | X85: 46235 | Y85: 1 | Z85: Normal | AA85: 0
A86: COD | B86: 3 | C86: Adja | D86: Adja | E86: CD540902 | F86: pcode | G86: 46237 | H86: deaths | I86: confirmed | J86: cumulative | K86: 1 | L86: count | M86: INRB-UMIE | N86: https://raw.githubusercontent.com/INRB-UMIE/BDBV2026-Data/main/data/insp_sitrep/processed/insp_sitrep__cumulative_confirmed_deaths__daily.csv | V86: 1 | W86: 0 | X86: 46236 | Y86: 1 | Z86: Normal | AA86: 0
A87: COD | B87: 3 | C87: Adja | D87: Adja | E87: CD540902 | F87: pcode | G87: 46238 | H87: deaths | I87: confirmed | J87: cumulative | K87: 1 | L87: count | M87: INRB-UMIE | N87: https://raw.githubusercontent.com/INRB-UMIE/BDBV2026-Data/main/data/insp_sitrep/processed/insp_sitrep__cumulative_confirmed_deaths__daily.csv | V87: 1 | W87: 0 | X87: 46237 | Y87: 1 | Z87: Normal | AA87: 0
... A147: COD | B147: 3 | C147: Adja | D147: Adja | E147: CD540902 | F147: pcode | G147: 46316 | H147: deaths | I147: confirmed | J147: cumulative | K147: 1 | L147: count | M147: INRB-UMIE | N147: https://raw.githubusercontent.com/INRB-UMIE/BDBV2026-Data/main/data/insp_sitrep/processed/insp_sitrep__cumulative_confirmed_deaths__daily.csv | V147: 1 | W147: 0 | X147: 46314 | Y147: 2 | Z147: Reporting Gap (>1 Day) | AA147: 0
A148: COD | B148: 3 | C148: Alimbongo | D148: Alimbongo | E148: CD610501 | F148: pcode | G148: 46297 | H148: cases | I148: confirmed | J148: cumulative | K148: 4 | L148: count | M148: INRB-UMIE | N148: https://raw.githubusercontent.com/INRB-UMIE/BDBV2026-Data/main/data/insp_sitrep/processed/insp_sitrep__cumulative_confirmed_cases__daily.csv | Z148: Normal
A149: COD | B149: 3 | C149: Alimbongo | D149: Alimbongo | E149: CD610501 | F149: pcode | G149: 46298 | H149: cases | I149: confirmed | J149: cumulative | K149: 4 | L149: count | M149: INRB-UMIE | N149: https://raw.githubusercontent.com/INRB-UMIE/BDBV2026-Data/main/data/insp_sitrep/processed/insp_sitrep__cumulative_confirmed_cases__daily.csv | V149: 4 | W149: 0 | X149: 46297 | Y149: 1 | Z149: Normal | AA149: 0
A150: COD | B150: 3 | C150: Alimbongo | D150: Alimbongo | E150: CD610501 | F150: pcode | G150: 46299 | H150: cases | I150: confirmed | J150: cumulative | K150: 4 | L150: count | M150: INRB-UMIE | N150: https://raw.githubusercontent.com/INRB-UMIE/BDBV2026-Data/main/data/insp_sitrep/processed/insp_sitrep__cumulative_confirmed_cases__daily.csv | V150: 4 | W150: 0 | X150: 46298 | Y150: 1 | Z150: Normal | AA150: 0
A151: COD | B151: 3 | C151: Alimbongo | D151: Alimbongo | E151: CD610501 | F151: pcode | G151: 46300 | H151: cases | I151: confirmed | J151: cumulative | K151: 4 | L151: count | M151: INRB-UMIE | N151: https://raw.githubusercontent.com/INRB-UMIE/BDBV2026-Data/main/data/insp_sitrep/processed/insp_sitrep__cumulative_confirmed_cases__daily.csv | V151: 4 | W151: 0 | X151: 46299 | Y151: 1 | Z151: Normal | AA151: 0
A152: COD | B152: 3 | C152: Alimbongo | D152: Alimbongo | E152: CD610501 | F152: pcode | G152: 46301 | H152: cases | I152: confirmed | J152: cumulative | K152: 5 | L152: count | M152: INRB-UMIE | N152: https://raw.githubusercontent.com/INRB-UMIE/BDBV2026-Data/main/data/insp_sitrep/processed/insp_sitrep__cumulative_confirmed_cases__daily.csv | V152: 4 | W152: 1 | X152: 46300 | Y152: 1 | Z152: Normal | AA152: 0.25
A153: COD | B153: 3 | C153: Alimbongo | D153: Alimbongo | E153: CD610501 | F153: pcode | G153: 46304 | H153: cases | I153: confirmed | J153: cumulative | K153: 5 | L153: count | M153: INRB-UMIE | N153: https://raw.githubusercontent.com/INRB-UMIE/BDBV2026-Data/main/data/insp_sitrep/processed/insp_sitrep__cumulative_confirmed_cases__daily.csv | V153: 5 | W153: 0 | X153: 46301 | Y153: 3 | Z153: Reporting Gap (>1 Day) | AA153: 0.2
A154: COD | B154: 3 | C154: Alimbongo | D154: Alimbongo | E154: CD610501 | F154: pcode | G154: 46305 | H154: cases | I154: confirmed | J154: cumulative | K154: 5 | L154: count | M154: INRB-UMIE | N154: https://raw.githubusercontent.com/INRB-UMIE/BDBV2026-Data/main/data/insp_sitrep/processed/insp_sitrep__cumulative_confirmed_cases__daily.csv | V154: 5 | W154: 0 | X154: 46304 | Y154: 1 | Z154: Normal | AA154: 0.16666667
A155: COD | B155: 3 | C155: Alimbongo | D155: Alimbongo | E155: CD610501 | F155: pcode | G155: 46306 | H155: cases | I155: confirmed | J155: cumulative | K155: 5 | L155: count | M155: INRB-UMIE | N155: https://raw.githubusercontent.com/INRB-UMIE/BDBV2026-Data/main/data/insp_sitrep/processed/insp_sitrep__cumulative_confirmed_cases__daily.csv | V155: 5 | W155: 0 | X155: 46305 | Y155: 1 | Z155: Normal | AA155: 0.14285714
A156: COD | B156: 3 | C156: Alimbongo | D156: Alimbongo | E156: CD610501 | F156: pcode | G156: 46307 | H156: cases | I156: confirmed | J156: cumulative | K156: 5 | L156: count | M156: INRB-UMIE | N156: https://raw.githubusercontent.com/INRB-UMIE/BDBV2026-Data/main/data/insp_sitrep/processed/insp_sitrep__cumulative_confirmed_cases__daily.csv | V156: 5 | W156: 0 | X156: 46306 | Y156: 1 | Z156: Normal | AA156: 0.14285714
A157: COD | B157: 3 | C157: Alimbongo | D157: Alimbongo | E157: CD610501 | F157: pcode | G157: 46308 | H157: cases | I157: confirmed | J157: cumulative | K157: 5 | L157: count | M157: INRB-UMIE | N157: https://raw.githubusercontent.com/INRB-UMIE/BDBV2026-Data/main/data/insp_sitrep/processed/insp_sitrep__cumulative_confirmed_cases__daily.csv | V157: 5 | W157: 0 | X157: 46307 | Y157: 1 | Z157: Normal | AA157: 0.14285714
A158: COD | B158: 3 | C158: Alimbongo | D158: Alimbongo | E158: CD610501 | F158: pcode | G158: 46309 | H158: cases | I158: confirmed | J158: cumulative | K158: 5 | L158: count | M158: INRB-UMIE | N158: https://raw.githubusercontent.com/INRB-UMIE/BDBV2026-Data/main/data/insp_sitrep/processed/insp_sitrep__cumulative_confirmed_cases__daily.csv | V158: 5 | W158: 0 | X158: 46308 | Y158: 1 | Z158: Normal | AA158: 0.14285714
...
